[2025-10-05T20:16:03.970+0000] {local_task_job_runner.py:120} INFO - ::group::Pre task execution logs
[2025-10-05T20:16:03.977+0000] {taskinstance.py:2076} INFO - Dependencies all met for dep_context=non-requeueable deps ti=<TaskInstance: Airflow_Lab1.load_model_task manual__2025-10-05T20:15:56.077158+00:00 [queued]>
[2025-10-05T20:16:03.981+0000] {taskinstance.py:2076} INFO - Dependencies all met for dep_context=requeueable deps ti=<TaskInstance: Airflow_Lab1.load_model_task manual__2025-10-05T20:15:56.077158+00:00 [queued]>
[2025-10-05T20:16:03.981+0000] {taskinstance.py:2306} INFO - Starting attempt 1 of 1
[2025-10-05T20:16:03.986+0000] {taskinstance.py:2330} INFO - Executing <Task(PythonOperator): load_model_task> on 2025-10-05 20:15:56.077158+00:00
[2025-10-05T20:16:03.989+0000] {warnings.py:112} WARNING - /home/***/.local/lib/python3.12/site-packages/***/task/task_runner/standard_task_runner.py:61: DeprecationWarning: This process (pid=186) is multi-threaded, use of fork() may lead to deadlocks in the child.
  pid = os.fork()

[2025-10-05T20:16:03.990+0000] {standard_task_runner.py:63} INFO - Started process 208 to run task
[2025-10-05T20:16:03.990+0000] {standard_task_runner.py:90} INFO - Running: ['***', 'tasks', 'run', 'Airflow_Lab1', 'load_model_task', 'manual__2025-10-05T20:15:56.077158+00:00', '--job-id', '20', '--raw', '--subdir', 'DAGS_FOLDER/***.py', '--cfg-path', '/tmp/tmp9vgnsk2o']
[2025-10-05T20:16:03.991+0000] {standard_task_runner.py:91} INFO - Job 20: Subtask load_model_task
[2025-10-05T20:16:04.010+0000] {task_command.py:426} INFO - Running <TaskInstance: Airflow_Lab1.load_model_task manual__2025-10-05T20:15:56.077158+00:00 [running]> on host b1c40b25947b
[2025-10-05T20:16:04.046+0000] {taskinstance.py:2648} INFO - Exporting env vars: AIRFLOW_CTX_DAG_OWNER='your_name' AIRFLOW_CTX_DAG_ID='Airflow_Lab1' AIRFLOW_CTX_TASK_ID='load_model_task' AIRFLOW_CTX_EXECUTION_DATE='2025-10-05T20:15:56.077158+00:00' AIRFLOW_CTX_TRY_NUMBER='1' AIRFLOW_CTX_DAG_RUN_ID='manual__2025-10-05T20:15:56.077158+00:00'
[2025-10-05T20:16:04.047+0000] {taskinstance.py:430} INFO - ::endgroup::
[2025-10-05T20:16:04.052+0000] {taskinstance.py:441} INFO - ::group::Post task execution logs
[2025-10-05T20:16:04.052+0000] {taskinstance.py:2905} ERROR - Task failed with exception
Traceback (most recent call last):
  File "/home/airflow/.local/lib/python3.12/site-packages/airflow/models/taskinstance.py", line 465, in _execute_task
    result = _execute_callable(context=context, **execute_callable_kwargs)
             ^^^^^^^^^^^^^^^^^^^^^^^^^^^^^^^^^^^^^^^^^^^^^^^^^^^^^^^^^^^^^
  File "/home/airflow/.local/lib/python3.12/site-packages/airflow/models/taskinstance.py", line 432, in _execute_callable
    return execute_callable(context=context, **execute_callable_kwargs)
           ^^^^^^^^^^^^^^^^^^^^^^^^^^^^^^^^^^^^^^^^^^^^^^^^^^^^^^^^^^^^
  File "/home/airflow/.local/lib/python3.12/site-packages/airflow/models/baseoperator.py", line 401, in wrapper
    return func(self, *args, **kwargs)
           ^^^^^^^^^^^^^^^^^^^^^^^^^^^
  File "/home/airflow/.local/lib/python3.12/site-packages/airflow/operators/python.py", line 235, in execute
    return_value = self.execute_callable()
                   ^^^^^^^^^^^^^^^^^^^^^^^
  File "/home/airflow/.local/lib/python3.12/site-packages/airflow/operators/python.py", line 252, in execute_callable
    return self.python_callable(*self.op_args, **self.op_kwargs)
           ^^^^^^^^^^^^^^^^^^^^^^^^^^^^^^^^^^^^^^^^^^^^^^^^^^^^^
  File "/opt/airflow/dags/src/lab.py", line 93, in load_model_elbow
    kl = KneeLocator(range(1, 50), sse, curve="convex", direction="decreasing")
         ^^^^^^^^^^^^^^^^^^^^^^^^^^^^^^^^^^^^^^^^^^^^^^^^^^^^^^^^^^^^^^^^^^^^^^
  File "/home/airflow/.local/lib/python3.12/site-packages/kneed/knee_locator.py", line 171, in __init__
    uspline = interpolate.interp1d(self.x, self.y)
              ^^^^^^^^^^^^^^^^^^^^^^^^^^^^^^^^^^^^
  File "/home/airflow/.local/lib/python3.12/site-packages/scipy/interpolate/_interpolate.py", line 286, in __init__
    _Interpolator1D.__init__(self, x, y, axis=axis)
  File "/home/airflow/.local/lib/python3.12/site-packages/scipy/interpolate/_polyint.py", line 58, in __init__
    self._set_yi(yi, xi=xi, axis=axis)
  File "/home/airflow/.local/lib/python3.12/site-packages/scipy/interpolate/_polyint.py", line 128, in _set_yi
    raise ValueError("x and y arrays must be equal in length along "
ValueError: x and y arrays must be equal in length along interpolation axis.
[2025-10-05T20:16:04.055+0000] {taskinstance.py:1206} INFO - Marking task as FAILED. dag_id=Airflow_Lab1, task_id=load_model_task, run_id=manual__2025-10-05T20:15:56.077158+00:00, execution_date=20251005T201556, start_date=20251005T201603, end_date=20251005T201604
[2025-10-05T20:16:04.060+0000] {standard_task_runner.py:110} ERROR - Failed to execute job 20 for task load_model_task (x and y arrays must be equal in length along interpolation axis.; 208)
[2025-10-05T20:16:04.088+0000] {local_task_job_runner.py:240} INFO - Task exited with return code 1
[2025-10-05T20:16:04.094+0000] {taskinstance.py:3503} INFO - 0 downstream tasks scheduled from follow-on schedule check
[2025-10-05T20:16:04.095+0000] {local_task_job_runner.py:222} INFO - ::endgroup::
